Error in folder: progressive-house on GPU 1
Traceback (most recent call last):
  File "/home/ddmanddman/buffett_use/query_ss/contras/pre_process/allin1_beatport.py", line 42, in process_folders
    # Analyze using allin1
              ^^^^^^^^^^^^
  File "/home/ddmanddman/miniconda3/envs/allin1/lib/python3.11/site-packages/allin1/analyze.py", line 152, in analyze
    results = sorted(results, key=lambda result: paths.index(result.path))
              ^^^^^^^^^^^^^^^^^^^^^^^^^^^^^^^^^^^^^^^^^^^^^^^^^^^^^^^^^^^^
  File "/home/ddmanddman/miniconda3/envs/allin1/lib/python3.11/site-packages/allin1/analyze.py", line 152, in <lambda>
    results = sorted(results, key=lambda result: paths.index(result.path))
                                                 ^^^^^^^^^^^^^^^^^^^^^^^^
ValueError: PosixPath('/mnt/gestalt/database/beatport/audio/audio/progressive-trance/c4f65844-d7ca-4af1-a3e8-bf20c0c5d0e8.mp3') is not in list

Error in folder: house on GPU 2
Traceback (most recent call last):
  File "/home/ddmanddman/buffett_use/query_ss/contras/pre_process/allin1_beatport.py", line 43, in process_folders
    results = allin1.analyze(
              ^^^^^^^^^^^^^^^
  File "/home/ddmanddman/miniconda3/envs/allin1/lib/python3.11/site-packages/allin1/analyze.py", line 152, in analyze
    results = sorted(results, key=lambda result: paths.index(result.path))
              ^^^^^^^^^^^^^^^^^^^^^^^^^^^^^^^^^^^^^^^^^^^^^^^^^^^^^^^^^^^^
  File "/home/ddmanddman/miniconda3/envs/allin1/lib/python3.11/site-packages/allin1/analyze.py", line 152, in <lambda>
    results = sorted(results, key=lambda result: paths.index(result.path))
                                                 ^^^^^^^^^^^^^^^^^^^^^^^^
ValueError: PosixPath('/mnt/gestalt/database/beatport/audio/audio/deep-house/5468a2b9-a9b1-4739-840a-6a63ce7dbb9c.mp3') is not in list

Error in folder: ['b36be413-daa5-484b-b3cc-78f3a6acfe85.mp3', 'c5f8d324-2bdb-4456-b76d-0c12fc8682e1.mp3', '7ac465df-dbee-4e51-9102-6d1c3afb66bc.mp3', 'b8a01c12-a84c-4c06-8afa-8158145bacfd.mp3'] on GPU 
Traceback (most recent call last):
  File "/home/ddmanddman/buffett_use/query_ss/contras/pre_process/allin1_test.py", line 36, in <module>
    results = allin1.analyze(
              ^^^^^^^^^^^^^^^
  File "/home/ddmanddman/miniconda3/envs/allin1/lib/python3.11/site-packages/allin1/analyze.py", line 86, in analyze
    check_paths(paths)
  File "/home/ddmanddman/miniconda3/envs/allin1/lib/python3.11/site-packages/allin1/helpers.py", line 85, in check_paths
    raise FileNotFoundError(f'Could not find the following files: {missing_files}')
FileNotFoundError: Could not find the following files: ['/home/ddmanddman/buffett_use/query_ss/contras/pre_process/7ac465df-dbee-4e51-9102-6d1c3afb66bc.mp3', '/home/ddmanddman/buffett_use/query_ss/contras/pre_process/b36be413-daa5-484b-b3cc-78f3a6acfe85.mp3', '/home/ddmanddman/buffett_use/query_ss/contras/pre_process/b8a01c12-a84c-4c06-8afa-8158145bacfd.mp3', '/home/ddmanddman/buffett_use/query_ss/contras/pre_process/c5f8d324-2bdb-4456-b76d-0c12fc8682e1.mp3']

Error in folder: ['/mnt/gestalt/database/beatport/audio/audio/psy-trance/b36be413-daa5-484b-b3cc-78f3a6acfe85.mp3', '/mnt/gestalt/database/beatport/audio/audio/progressive-house/c5f8d324-2bdb-4456-b76d-0c12fc8682e1.mp3', '/mnt/gestalt/database/beatport/audio/audio/electro-big-room/7ac465df-dbee-4e51-9102-6d1c3afb66bc.mp3', '/mnt/gestalt/database/beatport/audio/audio/house/b8a01c12-a84c-4c06-8afa-8158145bacfd.mp3'] on GPU 
Traceback (most recent call last):
  File "/home/ddmanddman/buffett_use/query_ss/contras/pre_process/allin1_test.py", line 37, in <module>
    results = allin1.analyze(
              ^^^^^^^^^^^^^^^
  File "/home/ddmanddman/miniconda3/envs/allin1/lib/python3.11/site-packages/allin1/analyze.py", line 118, in analyze
    demix_paths = demix(todo_paths, demix_dir, device)
                  ^^^^^^^^^^^^^^^^^^^^^^^^^^^^^^^^^^^^
  File "/home/ddmanddman/miniconda3/envs/allin1/lib/python3.11/site-packages/allin1/demix.py", line 30, in demix
    subprocess.run(
  File "/home/ddmanddman/miniconda3/envs/allin1/lib/python3.11/subprocess.py", line 571, in run
    raise CalledProcessError(retcode, process.args,
subprocess.CalledProcessError: Command '['/home/ddmanddman/miniconda3/envs/allin1/bin/python', '-m', 'demucs.separate', '--out', '/mnt/gestalt/home/ddmanddman/beatport_analyze', '--name', 'htdemucs', '--device', 'cuda:2', '/mnt/gestalt/database/beatport/audio/audio/electro-big-room/7ac465df-dbee-4e51-9102-6d1c3afb66bc.mp3', '/mnt/gestalt/database/beatport/audio/audio/house/b8a01c12-a84c-4c06-8afa-8158145bacfd.mp3', '/mnt/gestalt/database/beatport/audio/audio/progressive-house/c5f8d324-2bdb-4456-b76d-0c12fc8682e1.mp3', '/mnt/gestalt/database/beatport/audio/audio/psy-trance/b36be413-daa5-484b-b3cc-78f3a6acfe85.mp3']' returned non-zero exit status 1.

